Internal Server Error: /login/forgot_password/
Traceback (most recent call last):
  File "C:\Users\Aameshi Godara\Desktop\Internships\DOTSQUARES\Django\myvenv\Lib\site-packages\django\core\handlers\exception.py", line 55, in inner
    response = get_response(request)
               ^^^^^^^^^^^^^^^^^^^^^
  File "C:\Users\Aameshi Godara\Desktop\Internships\DOTSQUARES\Django\myvenv\Lib\site-packages\django\core\handlers\base.py", line 197, in _get_response
    response = wrapped_callback(request, *callback_args, **callback_kwargs)
               ^^^^^^^^^^^^^^^^^^^^^^^^^^^^^^^^^^^^^^^^^^^^^^^^^^^^^^^^^^^^
  File "C:\Users\Aameshi Godara\Desktop\Internships\DOTSQUARES\Django\blog\views.py", line 85, in forgot_password
    send_mail(
  File "C:\Users\Aameshi Godara\Desktop\Internships\DOTSQUARES\Django\myvenv\Lib\site-packages\django\core\mail\__init__.py", line 88, in send_mail
    return mail.send()
           ^^^^^^^^^^^
  File "C:\Users\Aameshi Godara\Desktop\Internships\DOTSQUARES\Django\myvenv\Lib\site-packages\django\core\mail\message.py", line 301, in send
    return self.get_connection(fail_silently).send_messages([self])
           ^^^^^^^^^^^^^^^^^^^^^^^^^^^^^^^^^^^^^^^^^^^^^^^^^^^^^^^^
  File "C:\Users\Aameshi Godara\Desktop\Internships\DOTSQUARES\Django\myvenv\Lib\site-packages\django\core\mail\backends\smtp.py", line 128, in send_messages
    new_conn_created = self.open()
                       ^^^^^^^^^^^
  File "C:\Users\Aameshi Godara\Desktop\Internships\DOTSQUARES\Django\myvenv\Lib\site-packages\django\core\mail\backends\smtp.py", line 95, in open
    self.connection.login(self.username, self.password)
  File "C:\Program Files\WindowsApps\PythonSoftwareFoundation.Python.3.12_3.12.1264.0_x64__qbz5n2kfra8p0\Lib\smtplib.py", line 750, in login
    raise last_exception
  File "C:\Program Files\WindowsApps\PythonSoftwareFoundation.Python.3.12_3.12.1264.0_x64__qbz5n2kfra8p0\Lib\smtplib.py", line 739, in login
    (code, resp) = self.auth(
                   ^^^^^^^^^^
  File "C:\Program Files\WindowsApps\PythonSoftwareFoundation.Python.3.12_3.12.1264.0_x64__qbz5n2kfra8p0\Lib\smtplib.py", line 662, in auth
    raise SMTPAuthenticationError(code, resp)
smtplib.SMTPAuthenticationError: (534, b'5.7.9 Application-specific password required. For more information, go to\n5.7.9  https://support.google.com/mail/?p=InvalidSecondFactor 98e67ed59e1d1-2ca353cc480sm2186576a91.53 - gsmtp')
"POST /login/forgot_password/ HTTP/1.1" 500 145
